test01_login_0____5 (case.test01.Testlogin) ... ERROR
test01_login_1____5 (case.test01.Testlogin) ... ERROR
test01_login_2____5 (case.test01.Testlogin) ... ERROR
test01_login_3____5 (case.test01.Testlogin) ... ERROR

======================================================================
ERROR: test01_login_0____5 (case.test01.Testlogin)
----------------------------------------------------------------------
Traceback (most recent call last):
  File "F:\study\python3.7\lib\site-packages\parameterized\parameterized.py", line 518, in standalone_func
    return func(*(a + p.args), **p.kwargs)
  File "F:\在家\web自动化\code02\case\test01.py", line 63, in test01_login
    self.kt.page_my()
  File "F:\在家\web自动化\code02\page\page_my.py", line 15, in page_my
    self.click_base(page.page_ceshi)
  File "F:\在家\web自动化\code02\base\base_page.py", line 18, in click_base
    self.find_base(loc).click()
  File "F:\study\python3.7\lib\site-packages\selenium\webdriver\remote\webelement.py", line 80, in click
    self._execute(Command.CLICK_ELEMENT)
  File "F:\study\python3.7\lib\site-packages\selenium\webdriver\remote\webelement.py", line 633, in _execute
    return self._parent.execute(command, params)
  File "F:\study\python3.7\lib\site-packages\selenium\webdriver\remote\webdriver.py", line 321, in execute
    self.error_handler.check_response(response)
  File "F:\study\python3.7\lib\site-packages\selenium\webdriver\remote\errorhandler.py", line 242, in check_response
    raise exception_class(message, screen, stacktrace)
selenium.common.exceptions.ElementClickInterceptedException: Message: element click intercepted: Element <li data-id="qa">...</li> is not clickable at point (716, 24). Other element would receive the click: <div id="triggerModal" class="modal modal-trigger  fade modal-scroll-inside in" aria-hidden="false" style="display: block;">...</div>
  (Session info: chrome=78.0.3904.97)


======================================================================
ERROR: test01_login_1____5 (case.test01.Testlogin)
----------------------------------------------------------------------
Traceback (most recent call last):
  File "F:\study\python3.7\lib\site-packages\parameterized\parameterized.py", line 518, in standalone_func
    return func(*(a + p.args), **p.kwargs)
  File "F:\在家\web自动化\code02\case\test01.py", line 63, in test01_login
    self.kt.page_my()
  File "F:\在家\web自动化\code02\page\page_my.py", line 15, in page_my
    self.click_base(page.page_ceshi)
  File "F:\在家\web自动化\code02\base\base_page.py", line 18, in click_base
    self.find_base(loc).click()
  File "F:\在家\web自动化\code02\base\base_page.py", line 14, in find_base
    until(lambda d: d.find_element(*loc))
  File "F:\study\python3.7\lib\site-packages\selenium\webdriver\support\wait.py", line 71, in until
    value = method(self._driver)
  File "F:\在家\web自动化\code02\base\base_page.py", line 14, in <lambda>
    until(lambda d: d.find_element(*loc))
  File "F:\study\python3.7\lib\site-packages\selenium\webdriver\remote\webdriver.py", line 978, in find_element
    'value': value})['value']
  File "F:\study\python3.7\lib\site-packages\selenium\webdriver\remote\webdriver.py", line 321, in execute
    self.error_handler.check_response(response)
  File "F:\study\python3.7\lib\site-packages\selenium\webdriver\remote\errorhandler.py", line 242, in check_response
    raise exception_class(message, screen, stacktrace)
selenium.common.exceptions.WebDriverException: Message: chrome not reachable
  (Session info: chrome=78.0.3904.97)


======================================================================
ERROR: test01_login_2____5 (case.test01.Testlogin)
----------------------------------------------------------------------
Traceback (most recent call last):
  File "F:\study\python3.7\lib\site-packages\parameterized\parameterized.py", line 518, in standalone_func
    return func(*(a + p.args), **p.kwargs)
  File "F:\在家\web自动化\code02\case\test01.py", line 63, in test01_login
    self.kt.page_my()
  File "F:\在家\web自动化\code02\page\page_my.py", line 15, in page_my
    self.click_base(page.page_ceshi)
  File "F:\在家\web自动化\code02\base\base_page.py", line 18, in click_base
    self.find_base(loc).click()
  File "F:\在家\web自动化\code02\base\base_page.py", line 14, in find_base
    until(lambda d: d.find_element(*loc))
  File "F:\study\python3.7\lib\site-packages\selenium\webdriver\support\wait.py", line 71, in until
    value = method(self._driver)
  File "F:\在家\web自动化\code02\base\base_page.py", line 14, in <lambda>
    until(lambda d: d.find_element(*loc))
  File "F:\study\python3.7\lib\site-packages\selenium\webdriver\remote\webdriver.py", line 978, in find_element
    'value': value})['value']
  File "F:\study\python3.7\lib\site-packages\selenium\webdriver\remote\webdriver.py", line 321, in execute
    self.error_handler.check_response(response)
  File "F:\study\python3.7\lib\site-packages\selenium\webdriver\remote\errorhandler.py", line 242, in check_response
    raise exception_class(message, screen, stacktrace)
selenium.common.exceptions.WebDriverException: Message: chrome not reachable
  (Session info: chrome=78.0.3904.97)


======================================================================
ERROR: test01_login_3____5 (case.test01.Testlogin)
----------------------------------------------------------------------
Traceback (most recent call last):
  File "F:\study\python3.7\lib\site-packages\parameterized\parameterized.py", line 518, in standalone_func
    return func(*(a + p.args), **p.kwargs)
  File "F:\在家\web自动化\code02\case\test01.py", line 63, in test01_login
    self.kt.page_my()
  File "F:\在家\web自动化\code02\page\page_my.py", line 15, in page_my
    self.click_base(page.page_ceshi)
  File "F:\在家\web自动化\code02\base\base_page.py", line 18, in click_base
    self.find_base(loc).click()
  File "F:\在家\web自动化\code02\base\base_page.py", line 14, in find_base
    until(lambda d: d.find_element(*loc))
  File "F:\study\python3.7\lib\site-packages\selenium\webdriver\support\wait.py", line 71, in until
    value = method(self._driver)
  File "F:\在家\web自动化\code02\base\base_page.py", line 14, in <lambda>
    until(lambda d: d.find_element(*loc))
  File "F:\study\python3.7\lib\site-packages\selenium\webdriver\remote\webdriver.py", line 978, in find_element
    'value': value})['value']
  File "F:\study\python3.7\lib\site-packages\selenium\webdriver\remote\webdriver.py", line 321, in execute
    self.error_handler.check_response(response)
  File "F:\study\python3.7\lib\site-packages\selenium\webdriver\remote\errorhandler.py", line 242, in check_response
    raise exception_class(message, screen, stacktrace)
selenium.common.exceptions.WebDriverException: Message: chrome not reachable
  (Session info: chrome=78.0.3904.97)


----------------------------------------------------------------------
Ran 4 tests in 65.259s

FAILED (errors=4)
